Workbook

Sheet Control Center
A1: LA BUDGETING — CONTROL CENTER
B2: System Status: | C2: =IF(Accounts!B10-Expenses!D5>=0,"OPERATIONAL","ACTION REQUIRED") | D2: ="Last Updated: " & TEXT(TODAY(),"DD-MMM-YYYY")
B4: AVAILABLE FUNDS
B6: 💰 Cash in hand | C6: =Accounts!B7 | D6: Physical cash available
B7: 🏦 Banks (Optima + Piraeus) | C7: =Accounts!B5+Accounts!B6 | D7: Bank account balances
B8: 🥇 Gold reserves | C8: =Accounts!B8 | D8: Estimated gold value
B9: ✦ TOTAL CONFIRMED FUNDS | C9: =Accounts!B10 | D9: All accounts (incl. extra)
B11: ⏳ TEPIX Loan | C11: =Accounts!B14 | D11: ="Status: " & Accounts!C14
B12: ⏳ Expecting (other incoming) | C12: =Accounts!B15 | D12: ="Status: " & Accounts!C15
B14: OVERVIEW
B16: 💼 Total Available Funds | C16: =Accounts!B10 | D16: All accounts (incl. extra)
B17: ⏳ Total Incoming | C17: =Accounts!B17 | D17: TEPIX + expecting + extra
B18: ✅ Total Paid | C18: =Expenses!D4 | D18: Paid across all projects
B19: 🧾 Total Committed | C19: =Expenses!D5 | D19: Upcoming across all projects
B20: 📊 Grand Total Budget | C20: =Expenses!D6 | D20: All projects (paid + upcoming)
B21: 💵 FREE CASH | C21: =Accounts!B10-Expenses!D5 | D21: Available after all commitments

Sheet Expenses
A1: ALL PROJECT EXPENSES | H1: PROJECTS — add up to 12 (type in column H)
H2: Project | I2: Paid | J2: Upcoming | K2: Total
A3: OVERVIEW — ALL PROJECTS | H3: Lazaraki 5 | I3: =IF($H3="","",SUMIFS(Table_Exp[Amount],Table_Exp[Project],$H3,Table_Exp[Status],"Paid")) | J3: =IF($H3="","",SUMIFS(Table_Exp[Amount],Table_Exp[Project],$H3,Table_Exp[Status],"Upcoming")) | K3: =IF($H3="","",I3+J3)
A4: ✅ Total Paid | D4: =SUMIF(Table_Exp[Status],"Paid",Table_Exp[Amount]) | E4: Payments to date (all projects) | H4: Agiou Konstantinou | I4: =IF($H4="","",SUMIFS(Table_Exp[Amount],Table_Exp[Project],$H4,Table_Exp[Status],"Paid")) | J4: =IF($H4="","",SUMIFS(Table_Exp[Amount],Table_Exp[Project],$H4,Table_Exp[Status],"Upcoming")) | K4: =IF($H4="","",I4+J4)
A5: ⏰ Total Upcoming | D5: =SUMIF(Table_Exp[Status],"Upcoming",Table_Exp[Amount]) | E5: Upcoming across all projects | I5: =IF($H5="","",SUMIFS(Table_Exp[Amount],Table_Exp[Project],$H5,Table_Exp[Status],"Paid")) | J5: =IF($H5="","",SUMIFS(Table_Exp[Amount],Table_Exp[Project],$H5,Table_Exp[Status],"Upcoming")) | K5: =IF($H5="","",I5+J5)
A6: 📊 Grand Total Budget | D6: =D4+D5 | E6: All projects (paid + upcoming) | I6: =IF($H6="","",SUMIFS(Table_Exp[Amount],Table_Exp[Project],$H6,Table_Exp[Status],"Paid")) | J6: =IF($H6="","",SUMIFS(Table_Exp[Amount],Table_Exp[Project],$H6,Table_Exp[Status],"Upcoming")) | K6: =IF($H6="","",I6+J6)
I7: =IF($H7="","",SUMIFS(Table_Exp[Amount],Table_Exp[Project],$H7,Table_Exp[Status],"Paid")) | J7: =IF($H7="","",SUMIFS(Table_Exp[Amount],Table_Exp[Project],$H7,Table_Exp[Status],"Upcoming")) | K7: =IF($H7="","",I7+J7)
I8: =IF($H8="","",SUMIFS(Table_Exp[Amount],Table_Exp[Project],$H8,Table_Exp[Status],"Paid")) | J8: =IF($H8="","",SUMIFS(Table_Exp[Amount],Table_Exp[Project],$H8,Table_Exp[Status],"Upcoming")) | K8: =IF($H8="","",I8+J8)
I9: =IF($H9="","",SUMIFS(Table_Exp[Amount],Table_Exp[Project],$H9,Table_Exp[Status],"Paid")) | J9: =IF($H9="","",SUMIFS(Table_Exp[Amount],Table_Exp[Project],$H9,Table_Exp[Status],"Upcoming")) | K9: =IF($H9="","",I9+J9)
I10: =IF($H10="","",SUMIFS(Table_Exp[Amount],Table_Exp[Project],$H10,Table_Exp[Status],"Paid")) | J10: =IF($H10="","",SUMIFS(Table_Exp[Amount],Table_Exp[Project],$H10,Table_Exp[Status],"Upcoming")) | K10: =IF($H10="","",I10+J10)
I11: =IF($H11="","",SUMIFS(Table_Exp[Amount],Table_Exp[Project],$H11,Table_Exp[Status],"Paid")) | J11: =IF($H11="","",SUMIFS(Table_Exp[Amount],Table_Exp[Project],$H11,Table_Exp[Status],"Upcoming")) | K11: =IF($H11="","",I11+J11)
A12: Project | B12: Item / Description | C12: Status | D12: Source | E12: Amount | F12: Notes | I12: =IF($H12="","",SUMIFS(Table_Exp[Amount],Table_Exp[Project],$H12,Table_Exp[Status],"Paid")) | J12: =IF($H12="","",SUMIFS(Table_Exp[Amount],Table_Exp[Project],$H12,Table_Exp[Status],"Upcoming")) | K12: =IF($H12="","",I12+J12)
A13: Lazaraki 5 | B13: Rent Advance | C13: Paid | D13: Piraeus Bank | E13: 5000 | I13: =IF($H13="","",SUMIFS(Table_Exp[Amount],Table_Exp[Project],$H13,Table_Exp[Status],"Paid")) | J13: =IF($H13="","",SUMIFS(Table_Exp[Amount],Table_Exp[Project],$H13,Table_Exp[Status],"Upcoming")) | K13: =IF($H13="","",I13+J13)
A14: Lazaraki 5 | B14: Rent Advance | C14: Paid | D14: Cash | E14: 1000 | I14: =IF($H14="","",SUMIFS(Table_Exp[Amount],Table_Exp[Project],$H14,Table_Exp[Status],"Paid")) | J14: =IF($H14="","",SUMIFS(Table_Exp[Amount],Table_Exp[Project],$H14,Table_Exp[Status],"Upcoming")) | K14: =IF($H14="","",I14+J14)
A15: Lazaraki 5 | B15: Demolition (Gkremismata) | C15: Paid | D15: Cash | E15: 2400 | F15: + TBD amounts pending | H15: TOTAL (all) | I15: =SUM(I3:I14) | J15: =SUM(J3:J14) | K15: =SUM(K3:K14)
A16: Lazaraki 5 | B16: Heating / Bathroom | C16: Paid | D16: Cash | E16: 1020 | F16: + TBD amounts pending
A17: Lazaraki 5 | B17: Engineer / Certificates | C17: Paid | D17: Cash | E17: 350 | F17: Complete
A18: Lazaraki 5 | B18: EOT Orestis | C18: Paid | D18: Cash | E18: 2000 | F18: €1,000 advance + €1,000 balance
A19: Lazaraki 5 | B19: Architects | C19: Paid | D19: Cash | E19: 4000
A20: Lazaraki 5 | B20: Accountant (Akis) | C20: Paid | D20: Cash | E20: 500
A21: Lazaraki 5 | B21: Common Expenses | C21: Paid | D21: Cash | E21: 290
A22: Lazaraki 5 | B22: Owner Tax (Eforia) | C22: Upcoming | D22: Piraeus Bank | E22: 39000
A23: Lazaraki 5 | B23: Notary + Lawyer | C23: Upcoming | D23: Piraeus Bank | E23: 20000
A24: Lazaraki 5 | B24: Notary + Lawyer | C24: Upcoming | D24: Cash | E24: 10000
A25: Lazaraki 5 | B25: Capital for Loan | C25: Upcoming | D25: TBD | E25: 350000 | F25: Required to release TEPIX loan
A26: Lazaraki 5 | B26: Construction VAT (FPA) | C26: Upcoming | D26: TBD | E26: 290000 | F26: Estimated
A27: Lazaraki 5 | B27: 4th Floor Offer | C27: Upcoming | D27: TBD | E27: 50000
A28: Agiou Konstantinou | B28: Tax Advance (Eforia) | C28: Upcoming | D28: Piraeus Bank | E28: 17300
A29: Agiou Konstantinou | B29: Tax Advance (Eforia) | C29: Upcoming | D29: Piraeus Bank | E29: 1450
A30: Agiou Konstantinou | B30: Nektaria | C30: Upcoming | D30: Cash | E30: 50000
A31: Agiou Konstantinou | B31: Notary / Lawyer | C31: Upcoming | D31: Cash | E31: 5000
A32: Agiou Konstantinou | B32: Construction | C32: Upcoming | D32: TBD | E32: 80000
A63: Tip: Select yellow cells for dropdowns. Press Tab from the last row to add a new row automatically.

Sheet Accounts
A1: ACCOUNTS & BALANCES
A3: YOUR MONEY TODAY
A4: Account | B4: Balance (€) | C4: Last Updated | D4: Notes
A5: Optima Bank | B5: 135000
A6: Piraeus Bank | B6: 30000
A7: Cash (physical) | B7: 220000 | D7: Keep updated
A8: Gold (est. value) | B8: 250000 | D8: Estimated market value
A10: TOTAL TODAY (Confirmed) | B10: =SUM(B5:B8)+SUM(B23:B32)
A13: INCOMING FUNDS (not yet received)
A14: TEPIX Loan (LAZARAKI ONLY — Piraeus) | B14: 850000 | C14: Pending | D14: Dedicated to Lazaraki renovation only
A15: Expecting (other incoming) | B15: 260000 | C15: Pending
A17: TOTAL INCOMING (if all received) | B17: =SUM(B14:B15)+SUM(B36:B40)
A19: Tip: Update yellow cells whenever balances change. Change TEPIX status to Received when funds arrive.
A21: EXTRA ACCOUNTS (add here)
A22: Account | B22: Balance (€) | C22: Last Updated | D22: Notes
A34: EXTRA INCOMING (add here)
A35: Account | B35: Balance (€) | C35: Last Updated | D35: Notes

Sheet Info
A1: HOW TO USE THIS WORKBOOK
B3: TAB OVERVIEW
B4: What each tab does:
B5: Control Center — Your main dashboard. Shows all money and project costs at a glance. Read-only — do not type here.
B6: Expenses — The full list of all project expenses. This is where you add, edit, and track every cost.
B7: Accounts — Your current balances: banks, cash, gold, and incoming funds (TEPIX loan, etc.).
B8: Info — This guide, in English.
B10: The Control Center updates automatically whenever you change anything in Expenses or Accounts.
B12: HOW TO ADD AN EXPENSE
B13: 1. Go to the “Expenses” tab.
B14: 2. Scroll down to the first empty yellow row (below the existing data).
B15: 3. Click the yellow cell in the “Project” column → pick from the dropdown. | C15: e.g. Lazaraki 5
B16: 4. Type a description in the next column. | C16: e.g. Plumber — kitchen
B17: 5. Click the “Status” cell → pick from the dropdown. | C17: Paid or Upcoming
B18: 6. Click the “Source” cell → pick which account paid. | C18: Cash, Optima Bank …
B19: 7. Type the amount (numbers only, no € sign).
B20: 8. Add any notes in the last column (optional).
B22: The Control Center totals update the moment you finish typing.
B24: HOW TO ADD A NEW PROJECT
B25: There are two things to do when a new project is added:
B26: 1. Go to “Expenses” and type the new project name in the “Project” column of an empty row.
B27: 2. Use the exact same project name every time you add an expense for it. | C27: Spelling must match!
B28: 3. The summary rows at the top of the Expenses tab will auto-calculate for that project.
B30: Consistency is key — “Lazaraki 5” and “lazaraki 5” are treated as different projects.
B32: HOW TO UPDATE BALANCES
B33: 1. Go to the “Accounts” tab.
B34: 2. Click the yellow cell next to the account you want to update.
B35: 3. Type the new balance and press Enter.
B36: 4. For TEPIX or “Expecting” funds: also update the Status column. | C36: Pending → Received
B38: Update balances regularly — the Control Center “Free Cash” figure depends on accurate balances.
B40: COLOUR GUIDE
B41: Green background = Paid / positive / confirmed
B42: Yellow / ivory = editable cell — you can type here
B43: Blue background = calculated formula — do not edit
B44: Orange tint = Lazaraki 5 section
B45: Purple tint = Agiou Konstantinou section
B46: Red background = alert or shortfall
B48: QUICK TIPS
B49: Yellow cells → editable. White or blue cells → formulas, do not touch.
B50: Always save the file after making changes (Ctrl + S).
...
